<robot name="mainarmass">
    <material name="gray"><color rgba="0.647 0.647 0.647 1" /></material>
    <material name="black"><color rgba="0.529 0.568 0.6 1" /></material>
    <material name="red"><color rgba="0.301 0.290 0.262 1" /></material>
    <material name="dark_gray"><color rgba="0.4 0.4 0.4 1" /></material>
    <material name="white"><color rgba="0.901 0.901 0.901 1" /></material>
    <material name="light_blue"><color rgba="0.811 0.858 0.898 1" /></material>

    <link name="root" />

    <link name="Base">
        <inertial>
            <mass value="0.219" />
            <origin xyz="0 0 0.005" rpy="0 0 0" />
            <inertia ixx="0.0009559" ixy="0" ixz="0" iyy="0.0009559" iyz="0" izz="0.00190814" />
        </inertial>
        <visual>
            <origin xyz="0 0 0" rpy="0 0 0" />
            <geometry><mesh filename="package://mainarmass/meshes/67.stl" scale="1 1 1" /></geometry>
            <material name="gray" />
        </visual>
        <collision>
            <origin xyz="0 0 0" rpy="0 0 0" />
            <geometry><mesh filename="package://mainarmass/meshes/67.stl" scale="1 1 1" /></geometry>
        </collision>
    </link>

    <link name="Shoulder">
        <inertial>
            <mass value="3.232" />
            <origin xyz="0.0015 0.0238 0.0500" rpy="0 0 0" />
            <inertia ixx="0.01827653" ixy="0.00349413" ixz="-0.00033063" iyy="0.01968154" iyz="-0.00175414" izz="0.03042546" />
        </inertial>
        <visual>
            <origin xyz="0.0637 0.1917 0.0902" rpy="0 0 0" />
            <geometry><mesh filename="package://mainarmass/meshes/63.stl" scale="1 1 1" /></geometry>
            <material name="dark_gray" />
        </visual>
        <collision>
            <origin xyz="0.0637 0.1917 0.0902" rpy="0 0 0" />
            <geometry><mesh filename="package://mainarmass/meshes/63.stl" scale="1 1 1" /></geometry>
        </collision>
    </link>

    <link name="UpperArm">
        <inertial>
            <mass value="1.456" />
            <origin xyz="0.0016 0.0003 0.0734" rpy="0 0 0" />
            <inertia ixx="0.02606584" ixy="-0.00147774" ixz="0.00295468" iyy="0.02661382" iyz="0.00583087" izz="0.00673394" />
        </inertial>
        <visual>
            <origin xyz="-0.0453 0.1279 0.0401" rpy="0 0 0" />
            <geometry><mesh filename="package://mainarmass/meshes/75.stl" scale="1 1 1" /></geometry>
            <material name="white" />
        </visual>
        <collision>
            <origin xyz="-0.0453 0.1279 0.0401" rpy="0 0 0" />
            <geometry><mesh filename="package://mainarmass/meshes/75.stl" scale="1 1 1" /></geometry>
        </collision>
    </link>

    <link name="Forearm">
        <inertial>
            <mass value="29.5338" />
            <origin xyz="-0.0255 -0.0694 -0.1516" rpy="0 0 0" />
            <inertia ixx="1.1872" ixy="-0.0724" ixz="-0.1595" iyy="1.0148" iyz="-0.4378" izz="0.2615" />
        </inertial>
        <visual>
            <origin xyz="0.0640 0.2460 -0.3971" rpy="0 0 0" />
            <geometry><mesh filename="package://mainarmass/meshes/79.stl" scale="1 1 1" /></geometry>
            <material name="black" />
        </visual>
        <collision>
            <origin xyz="0.0640 0.2460 -0.3971" rpy="0 0 0" />
            <geometry><mesh filename="package://mainarmass/meshes/79.stl" scale="1 1 1" /></geometry>
        </collision>
    </link>

    <link name="Wrist">
        <inertial>
            <mass value="0.086" />
            <origin xyz="-0.0285 0.0006 0.0133" rpy="0 0 0" />
            <inertia ixx="0.00004728" ixy="-0.00001086" ixz="0.00002008" iyy="0.00005686" iyz="0.00000813" izz="0.00003823" />
        </inertial>
        <visual>
            <origin xyz="0.1232 0.3795 0.0397" rpy="0 0 0" />
            <geometry><mesh filename="package://mainarmass/meshes/59.stl" scale="1 1 1" /></geometry>
            <material name="light_blue" />
        </visual>
        <collision>
            <origin xyz="0.1232 0.3795 0.0397" rpy="0 0 0" />
            <geometry><mesh filename="package://mainarmass/meshes/59.stl" scale="1 1 1" /></geometry>
        </collision>
    </link>

    <link name="Paddle">
        <inertial>
            <mass value="0.355" />
            <origin xyz="-0.0346 -0.0910 0.1368" rpy="0 0 0" />
            <inertia ixx="0.00254292" ixy="-0.0003235" ixz="0.00032513" iyy="0.00177002" iyz="0.00082579" izz="0.00103777" />
        </inertial>
        <visual>
            <origin xyz="0.1494 0.3836 -0.0516" rpy="0 0 0" />
            <geometry><mesh filename="package://mainarmass/meshes/71.stl" scale="1 1 1" /></geometry>
            <material name="red" />
        </visual>
        <collision>
            <origin xyz="0.1494 0.3836 -0.0516" rpy="0 0 0" />
            <geometry><mesh filename="package://mainarmass/meshes/71.stl" scale="1 1 1" /></geometry>
        </collision>
    </link>

    <joint name="root_to_base" type="fixed">
        <origin xyz="0 0 0" rpy="0 0 0" />
        <parent link="root" />
        <child link="Base" />
    </joint>

    <joint name="BaseRotate_0" type="continuous">
        <origin xyz="0 0 0" rpy="0.01712 0.04808 -0.38348" />
        <axis xyz="0.04806 -0.01710 -0.99869" />
        <parent link="Base" />
        <child link="Shoulder" />
        <limit effort="10.0" velocity="3.14" />
    </joint>

    <joint name="UpperArmRotate_0" type="continuous">
        <origin xyz="-0.01750 -0.03317 0.10511" rpy="-0.08249 -0.02327 0.02051" />
        <axis xyz="0.93476 -0.35525 0" />
        <parent link="Shoulder" />
        <child link="UpperArm" />
        <limit effort="10.0" velocity="3.14" />
    </joint>

    <joint name="ForeArmRotate_0" type="continuous">
        <origin xyz="-0.03355 -0.08830 0.45530" rpy="-0.06873 0.02609 -0.00089" />
        <axis xyz="0.93476 -0.35525 0" />
        <parent link="UpperArm" />
        <child link="Forearm" />
        <limit effort="10.0" velocity="3.14" />
    </joint>

    <joint name="WristRotate_0" type="continuous">
        <origin xyz="-0.10957 -0.19888 -0.43388" rpy="-0.84990 0.27810 3.0151" />
        <axis xyz="0.93476 -0.35525 0" />
        <parent link="Forearm" />
        <child link="Wrist" />
        <limit effort="10.0" velocity="3.14" />
    </joint>

    <joint name="PaddleRotate_0" type="continuous">
        <origin xyz="-0.04174 -0.00429 0.02647" rpy="0 0 0" />
        <axis xyz="0.20602 0.54209 -0.81467" />
        <parent link="Wrist" />
        <child link="Paddle" />
        <limit effort="10.0" velocity="3.14" />
    </joint>
</robot>